{
 "cells": [
  {
   "cell_type": "markdown",
   "metadata": {},
   "source": [
    "#### Loading the Weights and Biases into a New Model\n",
    "\n",
    "Sometimes you might want to adjust, or \"finetune\" a model that you have already trained and saved.\n",
    "\n",
    "However, loading saved Variables directly into a modified model can generate errors. Let's go over how to avoid these problems."
   ]
  },
  {
   "cell_type": "markdown",
   "metadata": {},
   "source": [
    "#### Naming Error\n",
    "\n",
    "TensorFlow uses a string identifier for Tensors and Operations called **name**. If a name is not given, TensorFlow will create one automatically. TensorFlow will give the first node the name **Type**, and then give the name **Type_number** for the subsequent nodes. Let's see how this can affect loading a model with a different order of **weights** and **bias**:"
   ]
  },
  {
   "cell_type": "code",
   "execution_count": 1,
   "metadata": {},
   "outputs": [
    {
     "name": "stdout",
     "output_type": "stream",
     "text": [
      "Save Weights: Variable:0\n",
      "Save Bias: Variable_1:0\n",
      "Load Weights: Variable_1:0\n",
      "Load Bias: Variable:0\n",
      "INFO:tensorflow:Restoring parameters from model.ckpt\n"
     ]
    },
    {
     "ename": "InvalidArgumentError",
     "evalue": "Assign requires shapes of both tensors to match. lhs shape= [3] rhs shape= [2,3]\n\t [[Node: save/Assign = Assign[T=DT_FLOAT, _class=[\"loc:@Variable\"], use_locking=true, validate_shape=true, _device=\"/job:localhost/replica:0/task:0/cpu:0\"](Variable, save/RestoreV2)]]\n\nCaused by op 'save/Assign', defined at:\n  File \"/anaconda/envs/tensorflow/lib/python3.5/runpy.py\", line 193, in _run_module_as_main\n    \"__main__\", mod_spec)\n  File \"/anaconda/envs/tensorflow/lib/python3.5/runpy.py\", line 85, in _run_code\n    exec(code, run_globals)\n  File \"/anaconda/envs/tensorflow/lib/python3.5/site-packages/ipykernel_launcher.py\", line 16, in <module>\n    app.launch_new_instance()\n  File \"/anaconda/envs/tensorflow/lib/python3.5/site-packages/traitlets/config/application.py\", line 658, in launch_instance\n    app.start()\n  File \"/anaconda/envs/tensorflow/lib/python3.5/site-packages/ipykernel/kernelapp.py\", line 477, in start\n    ioloop.IOLoop.instance().start()\n  File \"/anaconda/envs/tensorflow/lib/python3.5/site-packages/zmq/eventloop/ioloop.py\", line 177, in start\n    super(ZMQIOLoop, self).start()\n  File \"/anaconda/envs/tensorflow/lib/python3.5/site-packages/tornado/ioloop.py\", line 888, in start\n    handler_func(fd_obj, events)\n  File \"/anaconda/envs/tensorflow/lib/python3.5/site-packages/tornado/stack_context.py\", line 277, in null_wrapper\n    return fn(*args, **kwargs)\n  File \"/anaconda/envs/tensorflow/lib/python3.5/site-packages/zmq/eventloop/zmqstream.py\", line 440, in _handle_events\n    self._handle_recv()\n  File \"/anaconda/envs/tensorflow/lib/python3.5/site-packages/zmq/eventloop/zmqstream.py\", line 472, in _handle_recv\n    self._run_callback(callback, msg)\n  File \"/anaconda/envs/tensorflow/lib/python3.5/site-packages/zmq/eventloop/zmqstream.py\", line 414, in _run_callback\n    callback(*args, **kwargs)\n  File \"/anaconda/envs/tensorflow/lib/python3.5/site-packages/tornado/stack_context.py\", line 277, in null_wrapper\n    return fn(*args, **kwargs)\n  File \"/anaconda/envs/tensorflow/lib/python3.5/site-packages/ipykernel/kernelbase.py\", line 283, in dispatcher\n    return self.dispatch_shell(stream, msg)\n  File \"/anaconda/envs/tensorflow/lib/python3.5/site-packages/ipykernel/kernelbase.py\", line 235, in dispatch_shell\n    handler(stream, idents, msg)\n  File \"/anaconda/envs/tensorflow/lib/python3.5/site-packages/ipykernel/kernelbase.py\", line 399, in execute_request\n    user_expressions, allow_stdin)\n  File \"/anaconda/envs/tensorflow/lib/python3.5/site-packages/ipykernel/ipkernel.py\", line 196, in do_execute\n    res = shell.run_cell(code, store_history=store_history, silent=silent)\n  File \"/anaconda/envs/tensorflow/lib/python3.5/site-packages/ipykernel/zmqshell.py\", line 533, in run_cell\n    return super(ZMQInteractiveShell, self).run_cell(*args, **kwargs)\n  File \"/anaconda/envs/tensorflow/lib/python3.5/site-packages/IPython/core/interactiveshell.py\", line 2683, in run_cell\n    interactivity=interactivity, compiler=compiler, result=result)\n  File \"/anaconda/envs/tensorflow/lib/python3.5/site-packages/IPython/core/interactiveshell.py\", line 2787, in run_ast_nodes\n    if self.run_code(code, result):\n  File \"/anaconda/envs/tensorflow/lib/python3.5/site-packages/IPython/core/interactiveshell.py\", line 2847, in run_code\n    exec(code_obj, self.user_global_ns, self.user_ns)\n  File \"<ipython-input-1-02cf5d745f8d>\", line 29, in <module>\n    saver = tf.train.Saver()\n  File \"/anaconda/envs/tensorflow/lib/python3.5/site-packages/tensorflow/python/training/saver.py\", line 1056, in __init__\n    self.build()\n  File \"/anaconda/envs/tensorflow/lib/python3.5/site-packages/tensorflow/python/training/saver.py\", line 1086, in build\n    restore_sequentially=self._restore_sequentially)\n  File \"/anaconda/envs/tensorflow/lib/python3.5/site-packages/tensorflow/python/training/saver.py\", line 691, in build\n    restore_sequentially, reshape)\n  File \"/anaconda/envs/tensorflow/lib/python3.5/site-packages/tensorflow/python/training/saver.py\", line 419, in _AddRestoreOps\n    assign_ops.append(saveable.restore(tensors, shapes))\n  File \"/anaconda/envs/tensorflow/lib/python3.5/site-packages/tensorflow/python/training/saver.py\", line 155, in restore\n    self.op.get_shape().is_fully_defined())\n  File \"/anaconda/envs/tensorflow/lib/python3.5/site-packages/tensorflow/python/ops/state_ops.py\", line 270, in assign\n    validate_shape=validate_shape)\n  File \"/anaconda/envs/tensorflow/lib/python3.5/site-packages/tensorflow/python/ops/gen_state_ops.py\", line 47, in assign\n    use_locking=use_locking, name=name)\n  File \"/anaconda/envs/tensorflow/lib/python3.5/site-packages/tensorflow/python/framework/op_def_library.py\", line 768, in apply_op\n    op_def=op_def)\n  File \"/anaconda/envs/tensorflow/lib/python3.5/site-packages/tensorflow/python/framework/ops.py\", line 2336, in create_op\n    original_op=self._default_original_op, op_def=op_def)\n  File \"/anaconda/envs/tensorflow/lib/python3.5/site-packages/tensorflow/python/framework/ops.py\", line 1228, in __init__\n    self._traceback = _extract_stack()\n\nInvalidArgumentError (see above for traceback): Assign requires shapes of both tensors to match. lhs shape= [3] rhs shape= [2,3]\n\t [[Node: save/Assign = Assign[T=DT_FLOAT, _class=[\"loc:@Variable\"], use_locking=true, validate_shape=true, _device=\"/job:localhost/replica:0/task:0/cpu:0\"](Variable, save/RestoreV2)]]\n",
     "output_type": "error",
     "traceback": [
      "\u001b[0;31m---------------------------------------------------------------------------\u001b[0m",
      "\u001b[0;31mInvalidArgumentError\u001b[0m                      Traceback (most recent call last)",
      "\u001b[0;32m/anaconda/envs/tensorflow/lib/python3.5/site-packages/tensorflow/python/client/session.py\u001b[0m in \u001b[0;36m_do_call\u001b[0;34m(self, fn, *args)\u001b[0m\n\u001b[1;32m   1038\u001b[0m     \u001b[0;32mtry\u001b[0m\u001b[0;34m:\u001b[0m\u001b[0;34m\u001b[0m\u001b[0m\n\u001b[0;32m-> 1039\u001b[0;31m       \u001b[0;32mreturn\u001b[0m \u001b[0mfn\u001b[0m\u001b[0;34m(\u001b[0m\u001b[0;34m*\u001b[0m\u001b[0margs\u001b[0m\u001b[0;34m)\u001b[0m\u001b[0;34m\u001b[0m\u001b[0m\n\u001b[0m\u001b[1;32m   1040\u001b[0m     \u001b[0;32mexcept\u001b[0m \u001b[0merrors\u001b[0m\u001b[0;34m.\u001b[0m\u001b[0mOpError\u001b[0m \u001b[0;32mas\u001b[0m \u001b[0me\u001b[0m\u001b[0;34m:\u001b[0m\u001b[0;34m\u001b[0m\u001b[0m\n",
      "\u001b[0;32m/anaconda/envs/tensorflow/lib/python3.5/site-packages/tensorflow/python/client/session.py\u001b[0m in \u001b[0;36m_run_fn\u001b[0;34m(session, feed_dict, fetch_list, target_list, options, run_metadata)\u001b[0m\n\u001b[1;32m   1020\u001b[0m                                  \u001b[0mfeed_dict\u001b[0m\u001b[0;34m,\u001b[0m \u001b[0mfetch_list\u001b[0m\u001b[0;34m,\u001b[0m \u001b[0mtarget_list\u001b[0m\u001b[0;34m,\u001b[0m\u001b[0;34m\u001b[0m\u001b[0m\n\u001b[0;32m-> 1021\u001b[0;31m                                  status, run_metadata)\n\u001b[0m\u001b[1;32m   1022\u001b[0m \u001b[0;34m\u001b[0m\u001b[0m\n",
      "\u001b[0;32m/anaconda/envs/tensorflow/lib/python3.5/contextlib.py\u001b[0m in \u001b[0;36m__exit__\u001b[0;34m(self, type, value, traceback)\u001b[0m\n\u001b[1;32m     65\u001b[0m             \u001b[0;32mtry\u001b[0m\u001b[0;34m:\u001b[0m\u001b[0;34m\u001b[0m\u001b[0m\n\u001b[0;32m---> 66\u001b[0;31m                 \u001b[0mnext\u001b[0m\u001b[0;34m(\u001b[0m\u001b[0mself\u001b[0m\u001b[0;34m.\u001b[0m\u001b[0mgen\u001b[0m\u001b[0;34m)\u001b[0m\u001b[0;34m\u001b[0m\u001b[0m\n\u001b[0m\u001b[1;32m     67\u001b[0m             \u001b[0;32mexcept\u001b[0m \u001b[0mStopIteration\u001b[0m\u001b[0;34m:\u001b[0m\u001b[0;34m\u001b[0m\u001b[0m\n",
      "\u001b[0;32m/anaconda/envs/tensorflow/lib/python3.5/site-packages/tensorflow/python/framework/errors_impl.py\u001b[0m in \u001b[0;36mraise_exception_on_not_ok_status\u001b[0;34m()\u001b[0m\n\u001b[1;32m    465\u001b[0m           \u001b[0mcompat\u001b[0m\u001b[0;34m.\u001b[0m\u001b[0mas_text\u001b[0m\u001b[0;34m(\u001b[0m\u001b[0mpywrap_tensorflow\u001b[0m\u001b[0;34m.\u001b[0m\u001b[0mTF_Message\u001b[0m\u001b[0;34m(\u001b[0m\u001b[0mstatus\u001b[0m\u001b[0;34m)\u001b[0m\u001b[0;34m)\u001b[0m\u001b[0;34m,\u001b[0m\u001b[0;34m\u001b[0m\u001b[0m\n\u001b[0;32m--> 466\u001b[0;31m           pywrap_tensorflow.TF_GetCode(status))\n\u001b[0m\u001b[1;32m    467\u001b[0m   \u001b[0;32mfinally\u001b[0m\u001b[0;34m:\u001b[0m\u001b[0;34m\u001b[0m\u001b[0m\n",
      "\u001b[0;31mInvalidArgumentError\u001b[0m: Assign requires shapes of both tensors to match. lhs shape= [3] rhs shape= [2,3]\n\t [[Node: save/Assign = Assign[T=DT_FLOAT, _class=[\"loc:@Variable\"], use_locking=true, validate_shape=true, _device=\"/job:localhost/replica:0/task:0/cpu:0\"](Variable, save/RestoreV2)]]",
      "\nDuring handling of the above exception, another exception occurred:\n",
      "\u001b[0;31mInvalidArgumentError\u001b[0m                      Traceback (most recent call last)",
      "\u001b[0;32m<ipython-input-1-02cf5d745f8d>\u001b[0m in \u001b[0;36m<module>\u001b[0;34m()\u001b[0m\n\u001b[1;32m     35\u001b[0m \u001b[0;32mwith\u001b[0m \u001b[0mtf\u001b[0m\u001b[0;34m.\u001b[0m\u001b[0mSession\u001b[0m\u001b[0;34m(\u001b[0m\u001b[0;34m)\u001b[0m \u001b[0;32mas\u001b[0m \u001b[0msess\u001b[0m\u001b[0;34m:\u001b[0m\u001b[0;34m\u001b[0m\u001b[0m\n\u001b[1;32m     36\u001b[0m     \u001b[0;31m# Load the weights and bias - ERROR\u001b[0m\u001b[0;34m\u001b[0m\u001b[0;34m\u001b[0m\u001b[0m\n\u001b[0;32m---> 37\u001b[0;31m     \u001b[0msaver\u001b[0m\u001b[0;34m.\u001b[0m\u001b[0mrestore\u001b[0m\u001b[0;34m(\u001b[0m\u001b[0msess\u001b[0m\u001b[0;34m,\u001b[0m \u001b[0msave_file\u001b[0m\u001b[0;34m)\u001b[0m\u001b[0;34m\u001b[0m\u001b[0m\n\u001b[0m",
      "\u001b[0;32m/anaconda/envs/tensorflow/lib/python3.5/site-packages/tensorflow/python/training/saver.py\u001b[0m in \u001b[0;36mrestore\u001b[0;34m(self, sess, save_path)\u001b[0m\n\u001b[1;32m   1455\u001b[0m     \u001b[0mlogging\u001b[0m\u001b[0;34m.\u001b[0m\u001b[0minfo\u001b[0m\u001b[0;34m(\u001b[0m\u001b[0;34m\"Restoring parameters from %s\"\u001b[0m\u001b[0;34m,\u001b[0m \u001b[0msave_path\u001b[0m\u001b[0;34m)\u001b[0m\u001b[0;34m\u001b[0m\u001b[0m\n\u001b[1;32m   1456\u001b[0m     sess.run(self.saver_def.restore_op_name,\n\u001b[0;32m-> 1457\u001b[0;31m              {self.saver_def.filename_tensor_name: save_path})\n\u001b[0m\u001b[1;32m   1458\u001b[0m \u001b[0;34m\u001b[0m\u001b[0m\n\u001b[1;32m   1459\u001b[0m   \u001b[0;34m@\u001b[0m\u001b[0mstaticmethod\u001b[0m\u001b[0;34m\u001b[0m\u001b[0m\n",
      "\u001b[0;32m/anaconda/envs/tensorflow/lib/python3.5/site-packages/tensorflow/python/client/session.py\u001b[0m in \u001b[0;36mrun\u001b[0;34m(self, fetches, feed_dict, options, run_metadata)\u001b[0m\n\u001b[1;32m    776\u001b[0m     \u001b[0;32mtry\u001b[0m\u001b[0;34m:\u001b[0m\u001b[0;34m\u001b[0m\u001b[0m\n\u001b[1;32m    777\u001b[0m       result = self._run(None, fetches, feed_dict, options_ptr,\n\u001b[0;32m--> 778\u001b[0;31m                          run_metadata_ptr)\n\u001b[0m\u001b[1;32m    779\u001b[0m       \u001b[0;32mif\u001b[0m \u001b[0mrun_metadata\u001b[0m\u001b[0;34m:\u001b[0m\u001b[0;34m\u001b[0m\u001b[0m\n\u001b[1;32m    780\u001b[0m         \u001b[0mproto_data\u001b[0m \u001b[0;34m=\u001b[0m \u001b[0mtf_session\u001b[0m\u001b[0;34m.\u001b[0m\u001b[0mTF_GetBuffer\u001b[0m\u001b[0;34m(\u001b[0m\u001b[0mrun_metadata_ptr\u001b[0m\u001b[0;34m)\u001b[0m\u001b[0;34m\u001b[0m\u001b[0m\n",
      "\u001b[0;32m/anaconda/envs/tensorflow/lib/python3.5/site-packages/tensorflow/python/client/session.py\u001b[0m in \u001b[0;36m_run\u001b[0;34m(self, handle, fetches, feed_dict, options, run_metadata)\u001b[0m\n\u001b[1;32m    980\u001b[0m     \u001b[0;32mif\u001b[0m \u001b[0mfinal_fetches\u001b[0m \u001b[0;32mor\u001b[0m \u001b[0mfinal_targets\u001b[0m\u001b[0;34m:\u001b[0m\u001b[0;34m\u001b[0m\u001b[0m\n\u001b[1;32m    981\u001b[0m       results = self._do_run(handle, final_targets, final_fetches,\n\u001b[0;32m--> 982\u001b[0;31m                              feed_dict_string, options, run_metadata)\n\u001b[0m\u001b[1;32m    983\u001b[0m     \u001b[0;32melse\u001b[0m\u001b[0;34m:\u001b[0m\u001b[0;34m\u001b[0m\u001b[0m\n\u001b[1;32m    984\u001b[0m       \u001b[0mresults\u001b[0m \u001b[0;34m=\u001b[0m \u001b[0;34m[\u001b[0m\u001b[0;34m]\u001b[0m\u001b[0;34m\u001b[0m\u001b[0m\n",
      "\u001b[0;32m/anaconda/envs/tensorflow/lib/python3.5/site-packages/tensorflow/python/client/session.py\u001b[0m in \u001b[0;36m_do_run\u001b[0;34m(self, handle, target_list, fetch_list, feed_dict, options, run_metadata)\u001b[0m\n\u001b[1;32m   1030\u001b[0m     \u001b[0;32mif\u001b[0m \u001b[0mhandle\u001b[0m \u001b[0;32mis\u001b[0m \u001b[0;32mNone\u001b[0m\u001b[0;34m:\u001b[0m\u001b[0;34m\u001b[0m\u001b[0m\n\u001b[1;32m   1031\u001b[0m       return self._do_call(_run_fn, self._session, feed_dict, fetch_list,\n\u001b[0;32m-> 1032\u001b[0;31m                            target_list, options, run_metadata)\n\u001b[0m\u001b[1;32m   1033\u001b[0m     \u001b[0;32melse\u001b[0m\u001b[0;34m:\u001b[0m\u001b[0;34m\u001b[0m\u001b[0m\n\u001b[1;32m   1034\u001b[0m       return self._do_call(_prun_fn, self._session, handle, feed_dict,\n",
      "\u001b[0;32m/anaconda/envs/tensorflow/lib/python3.5/site-packages/tensorflow/python/client/session.py\u001b[0m in \u001b[0;36m_do_call\u001b[0;34m(self, fn, *args)\u001b[0m\n\u001b[1;32m   1050\u001b[0m         \u001b[0;32mexcept\u001b[0m \u001b[0mKeyError\u001b[0m\u001b[0;34m:\u001b[0m\u001b[0;34m\u001b[0m\u001b[0m\n\u001b[1;32m   1051\u001b[0m           \u001b[0;32mpass\u001b[0m\u001b[0;34m\u001b[0m\u001b[0m\n\u001b[0;32m-> 1052\u001b[0;31m       \u001b[0;32mraise\u001b[0m \u001b[0mtype\u001b[0m\u001b[0;34m(\u001b[0m\u001b[0me\u001b[0m\u001b[0;34m)\u001b[0m\u001b[0;34m(\u001b[0m\u001b[0mnode_def\u001b[0m\u001b[0;34m,\u001b[0m \u001b[0mop\u001b[0m\u001b[0;34m,\u001b[0m \u001b[0mmessage\u001b[0m\u001b[0;34m)\u001b[0m\u001b[0;34m\u001b[0m\u001b[0m\n\u001b[0m\u001b[1;32m   1053\u001b[0m \u001b[0;34m\u001b[0m\u001b[0m\n\u001b[1;32m   1054\u001b[0m   \u001b[0;32mdef\u001b[0m \u001b[0m_extend_graph\u001b[0m\u001b[0;34m(\u001b[0m\u001b[0mself\u001b[0m\u001b[0;34m)\u001b[0m\u001b[0;34m:\u001b[0m\u001b[0;34m\u001b[0m\u001b[0m\n",
      "\u001b[0;31mInvalidArgumentError\u001b[0m: Assign requires shapes of both tensors to match. lhs shape= [3] rhs shape= [2,3]\n\t [[Node: save/Assign = Assign[T=DT_FLOAT, _class=[\"loc:@Variable\"], use_locking=true, validate_shape=true, _device=\"/job:localhost/replica:0/task:0/cpu:0\"](Variable, save/RestoreV2)]]\n\nCaused by op 'save/Assign', defined at:\n  File \"/anaconda/envs/tensorflow/lib/python3.5/runpy.py\", line 193, in _run_module_as_main\n    \"__main__\", mod_spec)\n  File \"/anaconda/envs/tensorflow/lib/python3.5/runpy.py\", line 85, in _run_code\n    exec(code, run_globals)\n  File \"/anaconda/envs/tensorflow/lib/python3.5/site-packages/ipykernel_launcher.py\", line 16, in <module>\n    app.launch_new_instance()\n  File \"/anaconda/envs/tensorflow/lib/python3.5/site-packages/traitlets/config/application.py\", line 658, in launch_instance\n    app.start()\n  File \"/anaconda/envs/tensorflow/lib/python3.5/site-packages/ipykernel/kernelapp.py\", line 477, in start\n    ioloop.IOLoop.instance().start()\n  File \"/anaconda/envs/tensorflow/lib/python3.5/site-packages/zmq/eventloop/ioloop.py\", line 177, in start\n    super(ZMQIOLoop, self).start()\n  File \"/anaconda/envs/tensorflow/lib/python3.5/site-packages/tornado/ioloop.py\", line 888, in start\n    handler_func(fd_obj, events)\n  File \"/anaconda/envs/tensorflow/lib/python3.5/site-packages/tornado/stack_context.py\", line 277, in null_wrapper\n    return fn(*args, **kwargs)\n  File \"/anaconda/envs/tensorflow/lib/python3.5/site-packages/zmq/eventloop/zmqstream.py\", line 440, in _handle_events\n    self._handle_recv()\n  File \"/anaconda/envs/tensorflow/lib/python3.5/site-packages/zmq/eventloop/zmqstream.py\", line 472, in _handle_recv\n    self._run_callback(callback, msg)\n  File \"/anaconda/envs/tensorflow/lib/python3.5/site-packages/zmq/eventloop/zmqstream.py\", line 414, in _run_callback\n    callback(*args, **kwargs)\n  File \"/anaconda/envs/tensorflow/lib/python3.5/site-packages/tornado/stack_context.py\", line 277, in null_wrapper\n    return fn(*args, **kwargs)\n  File \"/anaconda/envs/tensorflow/lib/python3.5/site-packages/ipykernel/kernelbase.py\", line 283, in dispatcher\n    return self.dispatch_shell(stream, msg)\n  File \"/anaconda/envs/tensorflow/lib/python3.5/site-packages/ipykernel/kernelbase.py\", line 235, in dispatch_shell\n    handler(stream, idents, msg)\n  File \"/anaconda/envs/tensorflow/lib/python3.5/site-packages/ipykernel/kernelbase.py\", line 399, in execute_request\n    user_expressions, allow_stdin)\n  File \"/anaconda/envs/tensorflow/lib/python3.5/site-packages/ipykernel/ipkernel.py\", line 196, in do_execute\n    res = shell.run_cell(code, store_history=store_history, silent=silent)\n  File \"/anaconda/envs/tensorflow/lib/python3.5/site-packages/ipykernel/zmqshell.py\", line 533, in run_cell\n    return super(ZMQInteractiveShell, self).run_cell(*args, **kwargs)\n  File \"/anaconda/envs/tensorflow/lib/python3.5/site-packages/IPython/core/interactiveshell.py\", line 2683, in run_cell\n    interactivity=interactivity, compiler=compiler, result=result)\n  File \"/anaconda/envs/tensorflow/lib/python3.5/site-packages/IPython/core/interactiveshell.py\", line 2787, in run_ast_nodes\n    if self.run_code(code, result):\n  File \"/anaconda/envs/tensorflow/lib/python3.5/site-packages/IPython/core/interactiveshell.py\", line 2847, in run_code\n    exec(code_obj, self.user_global_ns, self.user_ns)\n  File \"<ipython-input-1-02cf5d745f8d>\", line 29, in <module>\n    saver = tf.train.Saver()\n  File \"/anaconda/envs/tensorflow/lib/python3.5/site-packages/tensorflow/python/training/saver.py\", line 1056, in __init__\n    self.build()\n  File \"/anaconda/envs/tensorflow/lib/python3.5/site-packages/tensorflow/python/training/saver.py\", line 1086, in build\n    restore_sequentially=self._restore_sequentially)\n  File \"/anaconda/envs/tensorflow/lib/python3.5/site-packages/tensorflow/python/training/saver.py\", line 691, in build\n    restore_sequentially, reshape)\n  File \"/anaconda/envs/tensorflow/lib/python3.5/site-packages/tensorflow/python/training/saver.py\", line 419, in _AddRestoreOps\n    assign_ops.append(saveable.restore(tensors, shapes))\n  File \"/anaconda/envs/tensorflow/lib/python3.5/site-packages/tensorflow/python/training/saver.py\", line 155, in restore\n    self.op.get_shape().is_fully_defined())\n  File \"/anaconda/envs/tensorflow/lib/python3.5/site-packages/tensorflow/python/ops/state_ops.py\", line 270, in assign\n    validate_shape=validate_shape)\n  File \"/anaconda/envs/tensorflow/lib/python3.5/site-packages/tensorflow/python/ops/gen_state_ops.py\", line 47, in assign\n    use_locking=use_locking, name=name)\n  File \"/anaconda/envs/tensorflow/lib/python3.5/site-packages/tensorflow/python/framework/op_def_library.py\", line 768, in apply_op\n    op_def=op_def)\n  File \"/anaconda/envs/tensorflow/lib/python3.5/site-packages/tensorflow/python/framework/ops.py\", line 2336, in create_op\n    original_op=self._default_original_op, op_def=op_def)\n  File \"/anaconda/envs/tensorflow/lib/python3.5/site-packages/tensorflow/python/framework/ops.py\", line 1228, in __init__\n    self._traceback = _extract_stack()\n\nInvalidArgumentError (see above for traceback): Assign requires shapes of both tensors to match. lhs shape= [3] rhs shape= [2,3]\n\t [[Node: save/Assign = Assign[T=DT_FLOAT, _class=[\"loc:@Variable\"], use_locking=true, validate_shape=true, _device=\"/job:localhost/replica:0/task:0/cpu:0\"](Variable, save/RestoreV2)]]\n"
     ]
    }
   ],
   "source": [
    "import tensorflow as tf\n",
    "\n",
    "# Remove the previous weights and bias\n",
    "tf.reset_default_graph()\n",
    "\n",
    "save_file = 'model.ckpt'\n",
    "\n",
    "# Two Tensor Variables: weights and bias\n",
    "weights = tf.Variable(tf.truncated_normal([2, 3]))\n",
    "bias = tf.Variable(tf.truncated_normal([3]))\n",
    "\n",
    "saver = tf.train.Saver()\n",
    "\n",
    "# Print the name of Weights and Bias\n",
    "print('Save Weights: {}'.format(weights.name))\n",
    "print('Save Bias: {}'.format(bias.name))\n",
    "\n",
    "with tf.Session() as sess:\n",
    "    sess.run(tf.global_variables_initializer())\n",
    "    saver.save(sess, save_file)\n",
    "\n",
    "# Remove the previous weights and bias\n",
    "tf.reset_default_graph()\n",
    "\n",
    "# Two Variables: weights and bias\n",
    "bias = tf.Variable(tf.truncated_normal([3]))\n",
    "weights = tf.Variable(tf.truncated_normal([2, 3]))\n",
    "\n",
    "saver = tf.train.Saver()\n",
    "\n",
    "# Print the name of Weights and Bias\n",
    "print('Load Weights: {}'.format(weights.name))\n",
    "print('Load Bias: {}'.format(bias.name))\n",
    "\n",
    "with tf.Session() as sess:\n",
    "    # Load the weights and bias - ERROR\n",
    "    saver.restore(sess, save_file)"
   ]
  },
  {
   "cell_type": "markdown",
   "metadata": {},
   "source": [
    "You'll notice that the **name** properties for **weights** and **bias** are different than when you saved the model. This is why the code produces the \"Assign requires shapes of both tensors to match\" error. The code **saver.restore(sess, save_file)** is trying to load weight data into bias and bias data into weights."
   ]
  },
  {
   "cell_type": "markdown",
   "metadata": {},
   "source": [
    "Instead of letting TensorFlow set the name property, let's set it manually:"
   ]
  },
  {
   "cell_type": "code",
   "execution_count": 2,
   "metadata": {},
   "outputs": [
    {
     "name": "stdout",
     "output_type": "stream",
     "text": [
      "Save Weights: weights_0:0\n",
      "Save Bias: bias_0:0\n",
      "Load Weights: weights_0:0\n",
      "Load Bias: bias_0:0\n",
      "INFO:tensorflow:Restoring parameters from model.ckpt\n",
      "Loaded Weights and Bias successfully.\n"
     ]
    }
   ],
   "source": [
    "import tensorflow as tf\n",
    "\n",
    "tf.reset_default_graph()\n",
    "\n",
    "save_file = 'model.ckpt'\n",
    "\n",
    "# Two Tensor Variables: weights and bias\n",
    "weights = tf.Variable(tf.truncated_normal([2, 3]), name='weights_0')\n",
    "bias = tf.Variable(tf.truncated_normal([3]), name='bias_0')\n",
    "\n",
    "saver = tf.train.Saver()\n",
    "\n",
    "# Print the name of Weights and Bias\n",
    "print('Save Weights: {}'.format(weights.name))\n",
    "print('Save Bias: {}'.format(bias.name))\n",
    "\n",
    "with tf.Session() as sess:\n",
    "    sess.run(tf.global_variables_initializer())\n",
    "    saver.save(sess, save_file)\n",
    "\n",
    "# Remove the previous weights and bias\n",
    "tf.reset_default_graph()\n",
    "\n",
    "# Two Variables: weights and bias\n",
    "bias = tf.Variable(tf.truncated_normal([3]), name='bias_0')\n",
    "weights = tf.Variable(tf.truncated_normal([2, 3]) ,name='weights_0')\n",
    "\n",
    "saver = tf.train.Saver()\n",
    "\n",
    "# Print the name of Weights and Bias\n",
    "print('Load Weights: {}'.format(weights.name))\n",
    "print('Load Bias: {}'.format(bias.name))\n",
    "\n",
    "with tf.Session() as sess:\n",
    "    # Load the weights and bias - No Error\n",
    "    saver.restore(sess, save_file)\n",
    "\n",
    "print('Loaded Weights and Bias successfully.')"
   ]
  },
  {
   "cell_type": "markdown",
   "metadata": {},
   "source": [
    "That worked! The Tensor names match and the data loaded correctly."
   ]
  }
 ],
 "metadata": {
  "kernelspec": {
   "display_name": "Python 3",
   "language": "python",
   "name": "python3"
  },
  "language_info": {
   "codemirror_mode": {
    "name": "ipython",
    "version": 3
   },
   "file_extension": ".py",
   "mimetype": "text/x-python",
   "name": "python",
   "nbconvert_exporter": "python",
   "pygments_lexer": "ipython3",
   "version": "3.5.3"
  }
 },
 "nbformat": 4,
 "nbformat_minor": 2
}
